Workbook

Sheet Closing Task
A1: Employee Code | B1: Task Category | C1: Detailed Monthly Tasks | D1: Reviewed by | E1: Approved by | F1: Preparation | G1: Review | H1: Approval
A2: RIM | B2: Payroll & Personnel | C2: Process and record Payroll, Final Pay, SL Conversions, and early retirement accrual. | D2: CKVC | E2: CKVC | F2: 1 Day | G2: 0.5 Day | H2: 0.5 Day
B3: Tax & Provisions | C3: Calculate and record the monthly Tax Provision and PPB Provision (performance bonuses). | D3: CKVC | E3: CKVC | F3: 1 Day | G3: 0.5 Day | H3: 0.5 Day
B4: Rent & Leases | C4: Record recurring monthly Rental Income/Expense and monthly amortization expense for employee hospitalization plans. | D4: CKVC | E4: CKVC | F4: 1 Day | G4: 0.5 Day | H4: 0.5 Day
B5: Accruals & Expenses | C5: Record accruals for Consultancy Fees and various routine General Expense Accruals.Estimated expense for which a vendor invoice has not yet been received. | D5: CKVC | E5: CKVC | F5: 1 Day | G5: 0.5 Day | H5: 0.5 Day
C6: Process and record Payments for various Cash Advances. Recording the funding/issuance of cash to employees for expected business expenditures. | D6: CKVC | E6: CKVC | F6: 1 Day | G6: 0.5 Day | H6: 0.5 Day
B7: Prior Period Review | C7: The necessary reversal or adjustment of temporary journal entries created in a previous month. Process reversal entries for the prior month's accruals and reclassifications. | D7: CKVC | E7: CKVC | F7: 1 Day | G7: 0.5 Day | H7: 0.5 Day
A8: BOM | B8: Amortization & Corporate | C8: Allocating prepaid expenses and capital costs over time to reflect true monthly resource consumption. Record monthly Depreciation, Amortization for vehicles/purchases/LOA, and Amortization for all technology licenses and shared service costs. | D8: RIM | E8: CKVC | F8: 1 Day | G8: 0.5 Day | H8: 0.5 Day
B9: Corporate Accruals | C9: Accrue monthly expenses for Management and Royalty fees, consulting fees, and funds for Innovations/Initiatives. Brief Detail: Recognizing an expense for internal projects or strategic corporate investments not yet formally invoiced. | D9: RIM | E9: CKVC | F9: 1 Day | G9: 0.5 Day | H9: 0.5 Day
B10: Insurance | C10: Monthly tracking and recording of premiums for various corporate insurance policies. Record monthly accrual for various Corporate Insurance types and amortize prepaid Health Insurance. | D10: RIM | E10: CKVC | F10: 1 Day | G10: 0.5 Day | H10: 0.5 Day
B11: Treasury & Other | C11: Non-operating financial activities including capital structure and compliance. Record monthly bank charges, perform revaluation of foreign currency bank accounts, and record the monthly expense portion of the Omnicom stock option grant. | D11: RIM | E11: CKVC | F11: 1 Day | G11: 0.5 Day | H11: 0.5 Day
B12: Prior Period Review | C12: Process reversal entries for all prior month Accruals (e.g., trainings, production/retainers). | D12: RIM | E12: CKVC | F12: 1 Day | G12: 0.5 Day | H12: 0.5 Day
B13: Regional Reporting | C13: Prepare reports for Flash, Wins & Losses and Revenue. | D13: RIM | E13: CKVC | F13: 1 Day | G13: 0.5 Day | H13: 0.5 Day
A14: JPAL | B14: Client Billings | C14: Recognizing revenue and billable costs based on client contracts and project status. Accrue estimated Production, Retainer Fees, Media Commission, Creative Fees, and OOPC. Recording estimated Out-of-Pocket Costs that will eventually be billed to a client. | D14: BOM | E14: CKVC | F14: 1 Day | G14: 0.5 Day | H14: 0.5 Day
B15: WIP/OOP Management | C15: Reconciling and reclassifying costs to ensure they are correctly categorized as billable (WIP) or internal (OOP). Perform month-end Reclassifications of OOP to WIP (moves client-related expenses to an active project account) and necessary Reclass WIP to OOP (moves costs back if non-billable). | D15: BOM | E15: CKVC | F15: 1 Day | G15: 0.5 Day | H15: 0.5 Day
B16: Amortization & Corporate | C16: Allocating prepaid expenses and capital costs over time to reflect true monthly resource consumption. Record monthly Amortization of the Business Permit and Amortization of LOA. | D16: BOM | E16: CKVC | F16: 1 Day | G16: 0.5 Day | H16: 0.5 Day
C17: Accrue estimated monthly Audit Fees. | D17: BOM | E17: CKVC | F17: 1 Day | G17: 0.5 Day | H17: 0.5 Day
C18: Record monthly Rental Expense/Income related to intercompany transactions. | D18: BOM | E18: CKVC | F18: 1 Day | G18: 0.5 Day | H18: 0.5 Day
C19: Perform month-end Revaluation of Intercompany Balances. Adjusting intercompany balances to reflect the correct value at the month-end exchange rate. | D19: BOM | E19: CKVC | F19: 1 Day | G19: 0.5 Day | H19: 0.5 Day
B20: AR Aging - WC | C20: Prepare reports for Working Captital related to AR | D20: BOM | E20: CKVC | F20: 1 Day | G20: 0.5 Day | H20: 0.5 Day
A21: LAS | B21: CA Liquidations | C21: Process and record Cash Advance (CA) Liquidations for specific project-related expenses. | D21: RIM | E21: CKVC | F21: 1 Day | G21: 0.5 Day | H21: 0.5 Day
B22: AP Aging - WC | C22: Prepare AP Aging report for working captital submission | D22: BOM | E22: CKVC | F22: 1 Day | G22: 0.5 Day | H22: 0.5 Day
B23: OOP | C23: Prepare HOW's summary report | D23: RIM | E23: CKVC | F23: 1 Day | G23: 0.5 Day | H23: 0.5 Day
B24: Asset & Lease Entries | C24: Recording transactions for financed assets and long-term commitments. Record monthly interest expense on leased assets and process amortization reclassifications for prepaid corporate fees. | D24: RIM | E24: CKVC | F24: 1 Day | G24: 0.5 Day | H24: 0.5 Day
B25: Reclassifications | C25: Correcting entries across the general ledger (GL). Process required reclassifications between specific GL accounts and between Marketing Expense categories. | D25: BOM | E25: CKVC | F25: 1 Day | G25: 0.5 Day | H25: 0.5 Day
A26: JLI | B26: VAT & Taxes | C26: Compile and record monthly Input VAT entries (VAT paid on purchases) and the monthly VAT Report (cumulative summary of VAT activity). | D26: JPAL | E26: CKVC | F26: 1 Day | G26: 0.5 Day | H26: 0.5 Day
B27: Accruals & Assets | C27: Recording estimated expenses for recurring monthly costs and recognizing non-fixed asset costs. Accrue recurring Expenses (estimated expense for regularly occurring services). | D27: LAS | E27: CKVC | F27: 1 Day | G27: 0.5 Day | H27: 0.5 Day
C28: Record the monthly recognition/capitalization of Other Computer Related Costs. | D28: LAS | E28: CKVC | F28: 1 Day | G28: 0.5 Day | H28: 0.5 Day
B29: AP Aging | C29: Prepare AP Aging report with detailed status per invoice. | D29: LAS | E29: CKVC | F29: 1 Day | G29: 0.5 Day | H29: 0.5 Day
A30: RMQB | B30: CA Liquidations | C30: Process and record Cash Advance (CA) Liquidations submitted by employees. | D30: RIM | E30: CKVC | F30: 1 Day | G30: 0.5 Day | H30: 0.5 Day
B31: Accruals & Assets | C31: Accrue monthly expense for Employee Cellphone Allowance | D31: LAS | E31: CKVC | F31: 1 Day | G31: 0.5 Day | H31: 0.5 Day
B32: Expense Reclassification | C32: Adjusting a recorded expense from one GL account to another to ensure correct reporting. Process reclassifications to correct expense categories (e.g., General Expense to Wireless and Meals). | D32: RIM | E32: CKVC | F32: 1 Day | G32: 0.5 Day | H32: 0.5 Day
A33: JAP | B33: VAT Reporting | C33: Compile, review, and record the monthly VAT Report (Initial and additional entries). | D33: JPAL | E33: CKVC | F33: 1 Day | G33: 0.5 Day | H33: 0.5 Day
B34: Job Transfers | C34: Adjusting costs or revenues between different internal project codes or job numbers. Process and record Transfers of Job Codes for consultancy fees and corporate projects. | D34: JPAL | E34: CKVC | F34: 1 Day | G34: 0.5 Day | H34: 0.5 Day
C35: Record specific GL reclassifications needed for month-end adjustments | D35: JPAL | E35: CKVC | F35: 1 Day | G35: 0.5 Day | H35: 0.5 Day
A36: JRMO | B36: Accruals | C36: Compile documents for the attachment of the revenue accruals. | D36: JPAL | E36: CKVC | F36: 1 Day | G36: 0.5 Day | H36: 0.5 Day
B37: WIP | C37: Prepare WIP schedule summary per Job# | D37: JPAL | E37: CKVC | F37: 1 Day | G37: 0.5 Day | H37: 0.5 Day

Sheet Closing Task - Gannt Chart
A1: Task Category | B1: Detailed Task | C1: Activity | D1: Employee | E1: Date | F1: Email
A2: I. Initial & Compliance | B2: Payroll Processing & Tax Provision
A3: I. Initial & Compliance | B3: 1. Process and record Payroll, Final Pay, SL Conversions, and early retirement accrual. | C3: Preparation | D3: RIM | E3: 45954 | F3: rey.meran@omc.com
A4: I. Initial & Compliance | B4: 1. Process and record Payroll, Final Pay, SL Conversions, and early retirement accrual. | C4: Review | D4: RIM (SFM) | E4: 45957 | F4: rey.meran@omc.com
A5: I. Initial & Compliance | B5: 1. Process and record Payroll, Final Pay, SL Conversions, and early retirement accrual. | C5: Approval | D5: CKVC (FD) | E5: 45957 | F5: khalil.veracruz@omc.com
A6: I. Initial & Compliance | B6: 2. Calculate and record the monthly Tax Provision and PPB Provision (performance bonuses). | C6: Preparation | D6: RIM | E6: 45957 | F6: rey.meran@omc.com
A7: I. Initial & Compliance | B7: 2. Calculate and record the monthly Tax Provision and PPB Provision (performance bonuses). | C7: Review | D7: RIM (SFM) | E7: 45958 | F7: rey.meran@omc.com
A8: I. Initial & Compliance | B8: 2. Calculate and record the monthly Tax Provision and PPB Provision (performance bonuses). | C8: Approval | D8: CKVC (FD) | E8: 45958 | F8: khalil.veracruz@omc.com
A9: I. Initial & Compliance | B9: VAT Data/Filing
A10: I. Initial & Compliance | B10: 1. Compile, review, and record the monthly VAT Report (Initial and additional entries). | C10: Preparation | D10: JAP | E10: 45957 | F10: jasmin.ignacio@omc.com
A11: I. Initial & Compliance | B11: 1. Compile, review, and record the monthly VAT Report (Initial and additional entries). | C11: Review | D11: JPAL | E11: 45958 | F11: jinky.paladin@omc.com
A12: I. Initial & Compliance | B12: 1. Compile, review, and record the monthly VAT Report (Initial and additional entries). | C12: Approval | D12: RIM (SFM) | E12: 45958 | F12: rey.meran@omc.com
A13: I. Initial & Compliance | B13: 2. Compile and record monthly Input VAT entries (VAT paid on purchases) and the monthly VAT Report (cumulative summary of VAT activity). | C13: Preparation | D13: JIL | E13: 45957 | F13: jerald.loterte@omc.com
A14: I. Initial & Compliance | B14: 2. Compile and record monthly Input VAT entries (VAT paid on purchases) and the monthly VAT Report (cumulative summary of VAT activity). | C14: Review | D14: JPAL | E14: 45958 | F14: jinky.paladin@omc.com
A15: I. Initial & Compliance | B15: 2. Compile and record monthly Input VAT entries (VAT paid on purchases) and the monthly VAT Report (cumulative summary of VAT activity). | C15: Approval | D15: RIM (SFM) | E15: 45958 | F15: rey.meran@omc.com
A16: I. Initial & Compliance | B16: CA Liquidations (All)
A17: I. Initial & Compliance | B17: 1. Process and record Cash Advance (CA) Liquidations for specific project-related expenses. | C17: Preparation | D17: LAS | E17: 45957 | F17: amor.lasaga@omc.com
A18: I. Initial & Compliance | B18: 1. Process and record Cash Advance (CA) Liquidations for specific project-related expenses. | C18: Review | D18: RIM (SFM) | E18: 45959 | F18: rey.meran@omc.com
A19: I. Initial & Compliance | B19: 1. Process and record Cash Advance (CA) Liquidations for specific project-related expenses. | C19: Approval | D19: CKVC (FD) | E19: 45959 | F19: khalil.veracruz@omc.com
A20: I. Initial & Compliance | B20: 2. Process and record Cash Advance (CA) Liquidations submitted by employees. | C20: Preparation | D20: RMQB | E20: 45957 | F20: sally.brillantes@omc.com
A21: I. Initial & Compliance | B21: 2. Process and record Cash Advance (CA) Liquidations submitted by employees. | C21: Review | D21: RIM (SFM) | E21: 45959 | F21: rey.meran@omc.com
A22: I. Initial & Compliance | B22: 2. Process and record Cash Advance (CA) Liquidations submitted by employees. | C22: Approval | D22: CKVC (FD) | E22: 45959 | F22: khalil.veracruz@omc.com
A23: II. Accruals & Amortization | B23: Accruals (Revenue/Fees)
A24: II. Accruals & Amortization | B24: 1. Record accruals for Consultancy Fees and various routine General Expense Accruals.Estimated expense for which a vendor invoice has not yet been received. | C24: Preparation | D24: RIM | E24: 45958 | F24: rey.meran@omc.com
A25: II. Accruals & Amortization | B25: 1. Record accruals for Consultancy Fees and various routine General Expense Accruals.Estimated expense for which a vendor invoice has not yet been received. | C25: Review | D25: CKVC (FD) | E25: 45959 | F25: khalil.veracruz@omc.com
A26: II. Accruals & Amortization | B26: 1. Record accruals for Consultancy Fees and various routine General Expense Accruals.Estimated expense for which a vendor invoice has not yet been received. | C26: Approval | D26: CKVC (FD) | E26: 45959 | F26: khalil.veracruz@omc.com
A27: II. Accruals & Amortization | B27: 2. Accrue monthly expenses for Management and Royalty fees, consulting fees, and funds for Innovations/Initiatives. Brief Detail: Recognizing an expense for internal projects or strategic corporate investments not yet formally invoiced. | C27: Preparation | D27: BOM | E27: 45957 | F27: beng.manalo@omc.com
A28: II. Accruals & Amortization | B28: 2. Accrue monthly expenses for Management and Royalty fees, consulting fees, and funds for Innovations/Initiatives. Brief Detail: Recognizing an expense for internal projects or strategic corporate investments not yet formally invoiced. | C28: Review | D28: RIM | E28: 45958 | F28: rey.meran@omc.com
A29: II. Accruals & Amortization | B29: 2. Accrue monthly expenses for Management and Royalty fees, consulting fees, and funds for Innovations/Initiatives. Brief Detail: Recognizing an expense for internal projects or strategic corporate investments not yet formally invoiced. | C29: Approval | D29: CKVC (FD) | E29: 45958 | F29: khalil.veracruz@omc.com
A30: II. Accruals & Amortization | B30: 3. Recognizing revenue and billable costs based on client contracts and project status. Accrue estimated Production, Retainer Fees, Media Commission, Creative Fees, and OOPC. Recording estimated Out-of-Pocket Costs that will eventually be billed to a client. | C30: Preparation | D30: JPAL | E30: 45957 | F30: jinky.paladin@omc.com
A31: II. Accruals & Amortization | B31: 3. Recognizing revenue and billable costs based on client contracts and project status. Accrue estimated Production, Retainer Fees, Media Commission, Creative Fees, and OOPC. Recording estimated Out-of-Pocket Costs that will eventually be billed to a client. | C31: Review | D31: BOM | E31: 45957 | F31: beng.manalo@omc.com
A32: II. Accruals & Amortization | B32: 3. Recognizing revenue and billable costs based on client contracts and project status. Accrue estimated Production, Retainer Fees, Media Commission, Creative Fees, and OOPC. Recording estimated Out-of-Pocket Costs that will eventually be billed to a client. | C32: Approval | D32: CKVC (FD) | E32: 45959 | F32: khalil.veracruz@omc.com
A33: II. Accruals & Amortization | B33: 4. Recording estimated expenses for recurring monthly costs and recognizing non-fixed asset costs. Accrue recurring Expenses (estimated expense for regularly occurring services). | C33: Preparation | D33: LAS | E33: 45958 | F33: amor.lasaga@omc.com
A34: II. Accruals & Amortization | B34: 4. Recording estimated expenses for recurring monthly costs and recognizing non-fixed asset costs. Accrue recurring Expenses (estimated expense for regularly occurring services). | C34: Review | D34: RIM | E34: 45959 | F34: rey.meran@omc.com
A35: II. Accruals & Amortization | B35: 4. Recording estimated expenses for recurring monthly costs and recognizing non-fixed asset costs. Accrue recurring Expenses (estimated expense for regularly occurring services). | C35: Approval | D35: CKVC (FD) | E35: 45959 | F35: khalil.veracruz@omc.com
... A42: II. Accruals & Amortization | B42: 7. Compile documents for the attachment of the revenue accruals. | C42: Preparation | D42: JOL | E42: 45959 | F42: jhoee.oliva@omc.com
A43: II. Accruals & Amortization | B43: Amortizations (IT/Fixed Assets)
A44: II. Accruals & Amortization | B44: 1. Record recurring monthly Rental Income/Expense and monthly amortization expense for employee hospitalization plans. | C44: Preparation | D44: RIM | E44: 45958 | F44: rey.meran@omc.com
A45: II. Accruals & Amortization | B45: 1. Record recurring monthly Rental Income/Expense and monthly amortization expense for employee hospitalization plans. | C45: Review | D45: RIM | E45: 45959 | F45: rey.meran@omc.com
A46: II. Accruals & Amortization | B46: 1. Record recurring monthly Rental Income/Expense and monthly amortization expense for employee hospitalization plans. | C46: Approval | D46: CKVC (FD) | E46: 45959 | F46: khalil.veracruz@omc.com
...

Sheet Tax Filing
A1: BIR Form | B1: Period Covered | C1: BIR Filing & Payment Deadline (2026) | D1: 1. Prep & File Request (Finance Supervisor) | E1: 2. Report Approval (Senior Finance Manager) | F1: 3. Payment Approval (Finance Director)
A2: 1601-C (Compensation) | B2: 45992 | C2: 45672 | D2: =WORKDAY(C2,-4,'Holidays & Calendar'!$A$2:$A$46) -> 45666 | E2: =WORKDAY(C2,-2,'Holidays & Calendar'!$A$2:$A$46) -> 45670 | F2: =WORKDAY(C2,-1,'Holidays & Calendar'!$A$2:$A$46) -> 45671
A3: 1601-C / 0619-E | B3: 46023 | C3: 45698 | D3: =WORKDAY(C3,-4,'Holidays & Calendar'!$A$2:$A$46) -> 45692 | E3: =WORKDAY(C3,-2,'Holidays & Calendar'!$A$2:$A$46) -> 45694 | F3: =WORKDAY(C3,-1,'Holidays & Calendar'!$A$2:$A$46) -> 45695
A4: 1601-C / 0619-E | B4: 46054 | C4: 45726 | D4: =WORKDAY(C4,-4,'Holidays & Calendar'!$A$2:$A$46) -> 45720 | E4: =WORKDAY(C4,-2,'Holidays & Calendar'!$A$2:$A$46) -> 45722 | F4: =WORKDAY(C4,-1,'Holidays & Calendar'!$A$2:$A$46) -> 45723
A5: 1601-C / 0619-E | B5: 46082 | C5: 45757 | D5: =WORKDAY(C5,-4,'Holidays & Calendar'!$A$2:$A$46) -> 45751 | E5: =WORKDAY(C5,-2,'Holidays & Calendar'!$A$2:$A$46) -> 45755 | F5: =WORKDAY(C5,-1,'Holidays & Calendar'!$A$2:$A$46) -> 45756
A6: 1601-C / 0619-E | B6: 46113 | C6: 45787 | D6: =WORKDAY(C6,-4,'Holidays & Calendar'!$A$2:$A$46) -> 45783 | E6: =WORKDAY(C6,-2,'Holidays & Calendar'!$A$2:$A$46) -> 45785 | F6: =WORKDAY(C6,-1,'Holidays & Calendar'!$A$2:$A$46) -> 45786
A7: 1601-C / 0619-E | B7: 46143 | C7: 45818 | D7: =WORKDAY(C7,-4,'Holidays & Calendar'!$A$2:$A$46) -> 45812 | E7: =WORKDAY(C7,-2,'Holidays & Calendar'!$A$2:$A$46) -> 45814 | F7: =WORKDAY(C7,-1,'Holidays & Calendar'!$A$2:$A$46) -> 45817
A8: 1601-C / 0619-E | B8: 46174 | C8: 45848 | D8: =WORKDAY(C8,-4,'Holidays & Calendar'!$A$2:$A$46) -> 45842 | E8: =WORKDAY(C8,-2,'Holidays & Calendar'!$A$2:$A$46) -> 45846 | F8: =WORKDAY(C8,-1,'Holidays & Calendar'!$A$2:$A$46) -> 45847
A9: 1601-C / 0619-E | B9: 46204 | C9: 45879 | D9: =WORKDAY(C9,-4,'Holidays & Calendar'!$A$2:$A$46) -> 45874 | E9: =WORKDAY(C9,-2,'Holidays & Calendar'!$A$2:$A$46) -> 45876 | F9: =WORKDAY(C9,-1,'Holidays & Calendar'!$A$2:$A$46) -> 45877
A10: 1601-C / 0619-E | B10: 46235 | C10: 45910 | D10: =WORKDAY(C10,-4,'Holidays & Calendar'!$A$2:$A$46) -> 45904 | E10: =WORKDAY(C10,-2,'Holidays & Calendar'!$A$2:$A$46) -> 45908 | F10: =WORKDAY(C10,-1,'Holidays & Calendar'!$A$2:$A$46) -> 45909
A11: 1601-C / 0619-E | B11: 46266 | C11: 46307 | D11: =WORKDAY(C11,-4,'Holidays & Calendar'!$A$2:$A$46) -> 46301 | E11: =WORKDAY(C11,-2,'Holidays & Calendar'!$A$2:$A$46) -> 46303 | F11: =WORKDAY(C11,-1,'Holidays & Calendar'!$A$2:$A$46) -> 46304
A12: 1601-C / 0619-E | B12: 46296 | C12: 45971 | D12: =WORKDAY(C12,-4,'Holidays & Calendar'!$A$2:$A$46) -> 45965 | E12: =WORKDAY(C12,-2,'Holidays & Calendar'!$A$2:$A$46) -> 45967 | F12: =WORKDAY(C12,-1,'Holidays & Calendar'!$A$2:$A$46) -> 45968
A13: 1601-C / 0619-E | B13: 46327 | C13: 46001 | D13: =WORKDAY(C13,-4,'Holidays & Calendar'!$A$2:$A$46) -> 45994 | E13: =WORKDAY(C13,-2,'Holidays & Calendar'!$A$2:$A$46) -> 45996 | F13: =WORKDAY(C13,-1,'Holidays & Calendar'!$A$2:$A$46) -> 46000
A14: 1601-EQ (Quarterly EWT) | B14: Q4 2025 | C14: 45687 | D14: =WORKDAY(C14,-4,'Holidays & Calendar'!$A$2:$A$46) -> 45681 | E14: =WORKDAY(C14,-2,'Holidays & Calendar'!$A$2:$A$46) -> 45685 | F14: =WORKDAY(C14,-1,'Holidays & Calendar'!$A$2:$A$46) -> 45686
A15: 1702-RT/EX (Income Tax) | B15: Annual 2025 | C15: 45762 | D15: =WORKDAY(C15,-4,'Holidays & Calendar'!$A$2:$A$46) -> 45756 | E15: =WORKDAY(C15,-2,'Holidays & Calendar'!$A$2:$A$46) -> 45758 | F15: =WORKDAY(C15,-1,'Holidays & Calendar'!$A$2:$A$46) -> 45761
A16: 2550Q (VAT) | B16: Q1 2026 | C16: 46139 | D16: =WORKDAY(C16,-4,'Holidays & Calendar'!$A$2:$A$46) -> 46133 | E16: =WORKDAY(C16,-2,'Holidays & Calendar'!$A$2:$A$46) -> 46135 | F16: =WORKDAY(C16,-1,'Holidays & Calendar'!$A$2:$A$46) -> 46136
A17: 1601-EQ (Quarterly EWT) | B17: Q1 2026 | C17: 45777 | D17: =WORKDAY(C17,-4,'Holidays & Calendar'!$A$2:$A$46) -> 45771 | E17: =WORKDAY(C17,-2,'Holidays & Calendar'!$A$2:$A$46) -> 45775 | F17: =WORKDAY(C17,-1,'Holidays & Calendar'!$A$2:$A$46) -> 45776
A18: 2550Q (VAT) | B18: Q2 2026 | C18: 46230 | D18: =WORKDAY(C18,-4,'Holidays & Calendar'!$A$2:$A$46) -> 46224 | E18: =WORKDAY(C18,-2,'Holidays & Calendar'!$A$2:$A$46) -> 46226 | F18: =WORKDAY(C18,-1,'Holidays & Calendar'!$A$2:$A$46) -> 46227
A19: 1702Q (Quarterly Income Tax) | B19: Q2 2026 | C19: 45807 | D19: =WORKDAY(C19,-4,'Holidays & Calendar'!$A$2:$A$46) -> 45803 | E19: =WORKDAY(C19,-2,'Holidays & Calendar'!$A$2:$A$46) -> 45805 | F19: =WORKDAY(C19,-1,'Holidays & Calendar'!$A$2:$A$46) -> 45806
A20: 1601-EQ (Quarterly EWT) | B20: Q2 2026 | C20: 45869 | D20: =WORKDAY(C20,-4,'Holidays & Calendar'!$A$2:$A$46) -> 45863 | E20: =WORKDAY(C20,-2,'Holidays & Calendar'!$A$2:$A$46) -> 45867 | F20: =WORKDAY(C20,-1,'Holidays & Calendar'!$A$2:$A$46) -> 45868
A21: 2550Q (VAT) | B21: Q3 2026 | C21: 46321 | D21: =WORKDAY(C21,-4,'Holidays & Calendar'!$A$2:$A$46) -> 46315 | E21: =WORKDAY(C21,-2,'Holidays & Calendar'!$A$2:$A$46) -> 46317 | F21: =WORKDAY(C21,-1,'Holidays & Calendar'!$A$2:$A$46) -> 46318
A22: 1702Q (Quarterly Income Tax) | B22: Q3 2026 | C22: 45898 | D22: =WORKDAY(C22,-4,'Holidays & Calendar'!$A$2:$A$46) -> 45894 | E22: =WORKDAY(C22,-2,'Holidays & Calendar'!$A$2:$A$46) -> 45896 | F22: =WORKDAY(C22,-1,'Holidays & Calendar'!$A$2:$A$46) -> 45897
A23: 1601-EQ (Quarterly EWT) | B23: Q3 2026 | C23: 45960 | D23: =WORKDAY(C23,-4,'Holidays & Calendar'!$A$2:$A$46) -> 45954 | E23: =WORKDAY(C23,-2,'Holidays & Calendar'!$A$2:$A$46) -> 45958 | F23: =WORKDAY(C23,-1,'Holidays & Calendar'!$A$2:$A$46) -> 45959
A26: Step | B26: Process Detail | C26: Target Completion | D26: Responsible Role | F26: Email
A27: 1. Preparation | B27: Gather data, prepare the BIR Form, and draft the payment request (e.g., check voucher). | C27: BIR Deadline - 4 Business Days | D27: Finance Supervisor | E27: BOM | F27: beng.manalo@omc.com
A28: 2. Report Approval | B28: Senior Finance Manager (SFM) reviews and approves the report data for accuracy and compliance. (File Request is submitted to SFM.) | C28: BIR Deadline - 2 Business Days | D28: Senior Finance Manager | E28: RIM | F28: rey.meran@omc.com
A29: 3. Payment Approval | B29: The approved report and payment request are routed. Finance Director (FD) reviews and approves the release of funds for remittance. | C29: BIR Deadline - 1 Business Day | D29: Finance Director | E29: CKVC | F29: khalil.veracruz@omc.com
A30: 4. Filing & Payment | B30: The approved form is Filed and the payment is Remitted (either electronically or over the counter). | C30: On or before the BIR Deadline | D30: Finance Supervisor | E30: BOM | F30: beng.manalo@omc.com

Sheet Holidays & Calendar
A1: Date | B1: Holiday Name | C1: Type | E1: WORKDAY CALCULATOR | I1: DYNAMIC CLOSING PERIOD DEADLINES
A2: 45999 | B2: Feast of the Immaculate Conception | C2: Special Non-Working | E2: Deadline Date: | F2: 46037 | G2: ← Enter deadline here | I2: Today's Date: | J2: =TODAY() -> 46021
A3: 46015 | B3: Christmas Eve | C3: Special Non-Working | E3: Days Before: | F3: -4 | G3: ← Negative = before deadline | I3: Closing Month: | J3: =EOMONTH(TODAY(),-1) -> 45991 | K3: ← Previous month end
A4: 46016 | B4: Christmas Day | C4: Regular Holiday | E4: Working Day Result: | F4: =WORKDAY(F2,F3,$A$2:$A$46) -> 46031 | G4: ← Skips weekends & holidays | I4: Closing Deadline: | J4: =WORKDAY(EOMONTH(TODAY(),0),-1,$A$2:$A$46) -> 46020 | K4: ← Last working day of current month
A5: 46021 | B5: Rizal Day | C5: Regular Holiday
A6: 46022 | B6: Last Day of the Year | C6: Special Non-Working | E6: FORMULA TO USE: | F6: =WORKDAY(deadline,-days,holidays) | I6: INPUT: Select Closing Period
A7: 46023 | B7: New Year's Day | C7: Regular Holiday | E7: Holiday Range: | F7: Holidays & Calendar'!$A$2:$A$46 | I7: Closing Year: | J7: 2025 | K7: ← Enter year
A8: 46070 | B8: Chinese New Year | C8: Special Non-Working | I8: Closing Month: | J8: 12 | K8: ← Enter month (1-12)
A9: 46101 | B9: Eid'l Fitr (End of Ramadan) | C9: Regular Holiday | E9: EXAMPLE: Tax Filing Deadlines | F9: Formula | G9: Description | I9: Period End Date: | J9: =EOMONTH(DATE(J7,J8,1),0) -> 46022 | K9: ← Auto-calculated
A10: 46114 | B10: Maundy Thursday | C10: Regular Holiday | E10: Prep (-4 days) | F10: =WORKDAY(C2,-4,Holidays) | G10: 4 business days before deadline | I10: Soft Close (WD-5): | J10: =WORKDAY(J9,-5,$A$2:$A$46) -> 46010 | K10: ← 5 working days before
A11: 46115 | B11: Good Friday | C11: Regular Holiday | E11: Review (-2 days) | F11: =WORKDAY(C2,-2,Holidays) | G11: 2 business days before deadline | I11: Hard Close: | J11: =WORKDAY(EOMONTH(J9,1),3,$A$2:$A$46) -> 46057 | K11: ← WD+3 of next month
A12: 46116 | B12: Black Saturday | C12: Special Non-Working | E12: Approval (-1 day) | F12: =WORKDAY(C2,-1,Holidays) | G12: 1 business day before deadline
A13: 46121 | B13: Araw ng Kagitingan | C13: Regular Holiday | I13: Task Category | J13: Task | K13: Days | L13: Deadline | M13: Day | N13: Status
A14: 46143 | B14: Labor Day | C14: Regular Holiday | E14: Note: Add new holidays to column A to automatically adjust all dates | I14: I. Initial & Compliance | J14: Payroll & Tax Provision | K14: -5 | L14: =WORKDAY($J$9,K14,$A$2:$A$46) -> 46010 | M14: =TEXT(L14,"ddd") -> Fri | N14: =IF(L14<$J$2,"✓ Done",IF(L14=$J$2,"⚠ TODAY","Pending")) -> ✓ Done
A15: 46169 | B15: Eid'l Adha (Feast of Sacrifice) | C15: Regular Holiday | J15: VAT Data/Filing | K15: -4 | L15: =WORKDAY($J$9,K15,$A$2:$A$46) -> 46013 | M15: =TEXT(L15,"ddd") -> Mon | N15: =IF(L15<$J$2,"✓ Done",IF(L15=$J$2,"⚠ TODAY","Pending")) -> ✓ Done
A16: 46185 | B16: Independence Day | C16: Regular Holiday | J16: CA Liquidations | K16: -4 | L16: =WORKDAY($J$9,K16,$A$2:$A$46) -> 46013 | M16: =TEXT(L16,"ddd") -> Mon | N16: =IF(L16<$J$2,"✓ Done",IF(L16=$J$2,"⚠ TODAY","Pending")) -> ✓ Done
A17: 46255 | B17: Ninoy Aquino Day | C17: Special Non-Working | I17: II. Accruals & Amortization | J17: Revenue Accruals | K17: -3 | L17: =WORKDAY($J$9,K17,$A$2:$A$46) -> 46014 | M17: =TEXT(L17,"ddd") -> Tue | N17: =IF(L17<$J$2,"✓ Done",IF(L17=$J$2,"⚠ TODAY","Pending")) -> ✓ Done
A18: 46265 | B18: National Heroes Day | C18: Regular Holiday | J18: Expense Accruals | K18: -3 | L18: =WORKDAY($J$9,K18,$A$2:$A$46) -> 46014 | M18: =TEXT(L18,"ddd") -> Tue | N18: =IF(L18<$J$2,"✓ Done",IF(L18=$J$2,"⚠ TODAY","Pending")) -> ✓ Done
A19: 46327 | B19: All Saints' Day | C19: Special Non-Working | J19: Depreciation & Amortization | K19: -2 | L19: =WORKDAY($J$9,K19,$A$2:$A$46) -> 46017 | M19: =TEXT(L19,"ddd") -> Fri | N19: =IF(L19<$J$2,"✓ Done",IF(L19=$J$2,"⚠ TODAY","Pending")) -> ✓ Done
A20: 46328 | B20: All Souls' Day | C20: Special Non-Working | J20: Insurance & Corporate | K20: -2 | L20: =WORKDAY($J$9,K20,$A$2:$A$46) -> 46017 | M20: =TEXT(L20,"ddd") -> Fri | N20: =IF(L20<$J$2,"✓ Done",IF(L20=$J$2,"⚠ TODAY","Pending")) -> ✓ Done
A21: 46356 | B21: Bonifacio Day | C21: Regular Holiday | J21: Intercompany Transactions | K21: -2 | L21: =WORKDAY($J$9,K21,$A$2:$A$46) -> 46017 | M21: =TEXT(L21,"ddd") -> Fri | N21: =IF(L21<$J$2,"✓ Done",IF(L21=$J$2,"⚠ TODAY","Pending")) -> ✓ Done
A22: 46364 | B22: Feast of the Immaculate Conception | C22: Special Non-Working | I22: III. WIP/Reconciliation | J22: WIP/OOP Reconciliation | K22: -1 | L22: =WORKDAY($J$9,K22,$A$2:$A$46) -> 46020 | M22: =TEXT(L22,"ddd") -> Mon | N22: =IF(L22<$J$2,"✓ Done",IF(L22=$J$2,"⚠ TODAY","Pending")) -> ✓ Done
A23: 46380 | B23: Christmas Eve | C23: Special Non-Working | J23: AP/AR Aging Reports | K23: -1 | L23: =WORKDAY($J$9,K23,$A$2:$A$46) -> 46020 | M23: =TEXT(L23,"ddd") -> Mon | N23: =IF(L23<$J$2,"✓ Done",IF(L23=$J$2,"⚠ TODAY","Pending")) -> ✓ Done
A24: 46381 | B24: Christmas Day | C24: Regular Holiday | I24: IV. Final Close | J24: Prior Period Reversals | K24: 0 | L24: =WORKDAY($J$9,K24,$A$2:$A$46) -> 46022 | M24: =TEXT(L24,"ddd") -> Wed | N24: =IF(L24<$J$2,"✓ Done",IF(L24=$J$2,"⚠ TODAY","Pending")) -> Pending
A25: 46386 | B25: Rizal Day | C25: Regular Holiday | J25: GL Reclassifications | K25: 1 | L25: =WORKDAY($J$9,K25,$A$2:$A$46) -> 46024 | M25: =TEXT(L25,"ddd") -> Fri | N25: =IF(L25<$J$2,"✓ Done",IF(L25=$J$2,"⚠ TODAY","Pending")) -> Pending
A26: 46387 | B26: Last Day of the Year | C26: Special Non-Working | J26: Flash Reports | K26: 2 | L26: =WORKDAY($J$9,K26,$A$2:$A$46) -> 46027 | M26: =TEXT(L26,"ddd") -> Mon | N26: =IF(L26<$J$2,"✓ Done",IF(L26=$J$2,"⚠ TODAY","Pending")) -> Pending
A27: 46388 | B27: New Year's Day | C27: Regular Holiday | J27: Working Capital Reports | K27: 3 | L27: =WORKDAY($J$9,K27,$A$2:$A$46) -> 46028 | M27: =TEXT(L27,"ddd") -> Tue | N27: =IF(L27<$J$2,"✓ Done",IF(L27=$J$2,"⚠ TODAY","Pending")) -> Pending
A28: 46426 | B28: Chinese New Year | C28: Special Non-Working | I28: V. Sign-off | J28: Final TB Review (SFM) | K28: 4 | L28: =WORKDAY($J$9,K28,$A$2:$A$46) -> 46029 | M28: =TEXT(L28,"ddd") -> Wed | N28: =IF(L28<$J$2,"✓ Done",IF(L28=$J$2,"⚠ TODAY","Pending")) -> Pending
A29: 46456 | B29: Eid'l Fitr (End of Ramadan) | C29: Regular Holiday | J29: Final TB Sign-off (FD) | K29: 5 | L29: =WORKDAY($J$9,K29,$A$2:$A$46) -> 46030 | M29: =TEXT(L29,"ddd") -> Thu | N29: =IF(L29<$J$2,"✓ Done",IF(L29=$J$2,"⚠ TODAY","Pending")) -> Pending
A30: 46471 | B30: Maundy Thursday | C30: Regular Holiday | J30: Regional Submission | K30: 6 | L30: =WORKDAY($J$9,K30,$A$2:$A$46) -> 46031 | M30: =TEXT(L30,"ddd") -> Fri | N30: =IF(L30<$J$2,"✓ Done",IF(L30=$J$2,"⚠ TODAY","Pending")) -> Pending
A31: 46472 | B31: Good Friday | C31: Regular Holiday
A32: 46473 | B32: Black Saturday | C32: Special Non-Working | I32: TAX FILING DEADLINES
A33: 46486 | B33: Araw ng Kagitingan | C33: Regular Holiday | I33: BIR Form | J33: Description | K33: BIR Deadline | L33: Prep (-4 WD) | M33: Review (-2 WD) | N33: Approval (-1 WD)
A34: 46508 | B34: Labor Day | C34: Regular Holiday | I34: 1601-C / 0619-E | J34: Monthly Withholding Tax | K34: =DATE(IF(J8=12,J7+1,J7),IF(J8=12,1,J8+1),10) -> 46032 | L34: =WORKDAY(K34,-4,$A$2:$A$46) -> 46028 | M34: =WORKDAY(K34,-2,$A$2:$A$46) -> 46030 | N34: =WORKDAY(K34,-1,$A$2:$A$46) -> 46031
A35: 46523 | B35: Eid'l Adha (Feast of Sacrifice) | C35: Regular Holiday | I35: 2550M | J35: Monthly VAT | K35: =DATE(IF(J8=12,J7+1,J7),IF(J8=12,1,J8+1),20) -> 46042 | L35: =WORKDAY(K35,-4,$A$2:$A$46) -> 46036 | M35: =WORKDAY(K35,-2,$A$2:$A$46) -> 46038 | N35: =WORKDAY(K35,-1,$A$2:$A$46) -> 46041
A36: 46550 | B36: Independence Day | C36: Regular Holiday
A37: 46620 | B37: Ninoy Aquino Day | C37: Special Non-Working | I37: QUARTERLY (if applicable)
A38: 46629 | B38: National Heroes Day | C38: Regular Holiday | I38: 1601-EQ | J38: Quarterly Expanded W/Tax | K38: =IF(OR(J8=3,J8=6,J8=9,J8=12),EOMONTH(J9,1),"N/A") -> 46053 | L38: =IF(K38="N/A","N/A",WORKDAY(K38,-4,$A$2:$A$46)) -> 46049 | M38: =IF(K38="N/A","N/A",WORKDAY(K38,-2,$A$2:$A$46)) -> 46051 | N38: =IF(K38="N/A","N/A",WORKDAY(K38,-1,$A$2:$A$46)) -> 46052
A39: 46692 | B39: All Saints' Day | C39: Special Non-Working | I39: 2550Q | J39: Quarterly VAT | K39: =IF(OR(J8=3,J8=6,J8=9,J8=12),DATE(IF(J8=12,J7+1,J7),IF(J8=12,1,J8+1),25),"N/A") -> 46047 | L39: =IF(K39="N/A","N/A",WORKDAY(K39,-4,$A$2:$A$46)) -> 46042 | M39: =IF(K39="N/A","N/A",WORKDAY(K39,-2,$A$2:$A$46)) -> 46044 | N39: =IF(K39="N/A","N/A",WORKDAY(K39,-1,$A$2:$A$46)) -> 46045
A40: 46693 | B40: All Souls' Day | C40: Special Non-Working | I40: 1702Q | J40: Quarterly Income Tax | K40: =IF(OR(J8=3,J8=6,J8=9),DATE(J7,J8+2,15),"N/A") -> N/A | L40: =IF(K40="N/A","N/A",WORKDAY(K40,-4,$A$2:$A$46)) -> N/A | M40: =IF(K40="N/A","N/A",WORKDAY(K40,-2,$A$2:$A$46)) -> N/A | N40: =IF(K40="N/A","N/A",WORKDAY(K40,-1,$A$2:$A$46)) -> N/A
...
