Workbook

Sheet 2550-M
A1: Republic of the Philippines Department of Finance Bureau of Internal Revenue | D1: BIR Form No.
D2: 2550-M
A3: Monthly Value-Added Tax Declaration
A4: January 2023 (ENCS)
A6: Part I — Background Information
A7: 1 | B7: TIN
A8: 2 | B8: RDO Code
A9: 3 | B9: Taxpayer's Name
A10: 4 | B10: Registered Address
A11: 5 | B11: Zip Code
A12: 6 | B12: Line of Business / Occupation
A13: 7 | B13: For the Month (MM/YYYY)
A14: 8 | B14: Amendment? (Yes/No)
A16: Part II — Computation of Tax
A17: Schedule 1 — Sales/Receipts/Revenue
D18: Amount | F18: Output Tax
A19: 9A | B19: Vatable Sales
A20: 9B | B20: Sales to Government — Final Withholding
A21: 9C | B21: Zero-Rated Sales/Receipts
A22: 9D | B22: Exempt Sales/Receipts
A23: 10 | B23: Total Sales/Receipts (Sum 9A to 9D) | D23: =SUM(D19:D22)
A25: 11A | B25: Output Tax on Vatable Sales (9A x 12%) | F25: =D19*0.12
A26: 11B | B26: Output Tax on Sales to Government (9B x 12%) | F26: =D20*0.12
A27: 12 | B27: Total Output Tax (11A + 11B) | F27: =F25+F26
A29: Schedule 2 — Domestic Purchases/Payments
D30: Amount | F30: Input Tax
A31: 13A | B31: Purchase of Capital Goods exceeding PHP 1M
A32: 13B | B32: Purchase of Capital Goods not exceeding PHP 1M
A33: 13C | B33: Purchase of Goods other than Capital Goods
A34: 13D | B34: Purchase of Services
A35: 13E | B35: Purchase of Services by Non-Residents
A36: 13F | B36: Purchase Not Qualified for Input Tax
A37: 14 | B37: Total Domestic Purchases (Sum 13A to 13F) | D37: =SUM(D31:D36)
A39: 15A | B39: Input Tax on Capital Goods (13A+13B) x 12% | F39: =(D31+D32)*0.12
A40: 15B | B40: Input Tax on Goods Other than Capital (13C x 12%) | F40: =D33*0.12
A41: 15C | B41: Input Tax on Services (13D x 12%) | F41: =D34*0.12
A42: 15D | B42: Input Tax on Non-Resident Services (13E x 12%) | F42: =D35*0.12
A43: 16 | B43: Input Tax Deferred from Previous Period | F43: 0
A44: 17 | B44: Other Credits/Transitional Input Tax | F44: 0
A45: 18 | B45: Total Allowable Input Tax (Sum 15A-15D + 16 + 17) | F45: =SUM(F39:F44)
...

Sheet eFPS Ready
A1: eFPS Filing Data — BIR 2550-M
A3: Form Type | B3: 2550M
A4: TIN | B4: ='2550-M'!D7
A5: Return Period | B5: ='2550-M'!D13
A6: Vatable Sales | B6: ='2550-M'!D19
A7: Sales to Govt | B7: ='2550-M'!D20
A8: Zero-Rated Sales | B8: ='2550-M'!D21
A9: Exempt Sales | B9: ='2550-M'!D22
A10: Total Output VAT | B10: ='2550-M'!F27
A11: Total Input VAT | B11: ='2550-M'!F45
A12: VAT Payable | B12: ='2550-M'!F48
A13: Excess Input VAT | B13: ='2550-M'!F49
A14: Net VAT Payable | B14: ='2550-M'!F52
A15: TOTAL DUE | B15: ='2550-M'!F58
